[2025-07-17T14:27:48.810+0700] {local_task_job_runner.py:120} INFO - ::group::Pre task execution logs
[2025-07-17T14:27:48.819+0700] {taskinstance.py:2076} INFO - Dependencies all met for dep_context=non-requeueable deps ti=<TaskInstance: weather_dag.transform_load_weather_data manual__2025-07-17T07:27:41.504834+00:00 [queued]>
[2025-07-17T14:27:48.822+0700] {taskinstance.py:2076} INFO - Dependencies all met for dep_context=requeueable deps ti=<TaskInstance: weather_dag.transform_load_weather_data manual__2025-07-17T07:27:41.504834+00:00 [queued]>
[2025-07-17T14:27:48.823+0700] {taskinstance.py:2306} INFO - Starting attempt 1 of 3
[2025-07-17T14:27:48.847+0700] {taskinstance.py:2330} INFO - Executing <Task(PythonOperator): transform_load_weather_data> on 2025-07-17 07:27:41.504834+00:00
[2025-07-17T14:27:48.851+0700] {standard_task_runner.py:63} INFO - Started process 6999 to run task
[2025-07-17T14:27:48.865+0700] {standard_task_runner.py:90} INFO - Running: ['airflow', 'tasks', 'run', 'weather_dag', 'transform_load_weather_data', 'manual__2025-07-17T07:27:41.504834+00:00', '--job-id', '17', '--raw', '--subdir', 'DAGS_FOLDER/weather_dag.py', '--cfg-path', '/tmp/tmpfunbvvg9']
[2025-07-17T14:27:48.866+0700] {standard_task_runner.py:91} INFO - Job 17: Subtask transform_load_weather_data
[2025-07-17T14:27:48.918+0700] {task_command.py:426} INFO - Running <TaskInstance: weather_dag.transform_load_weather_data manual__2025-07-17T07:27:41.504834+00:00 [running]> on host MSI.
[2025-07-17T14:27:48.992+0700] {taskinstance.py:2648} INFO - Exporting env vars: AIRFLOW_CTX_DAG_EMAIL='menglimchea@gmail.com' AIRFLOW_CTX_DAG_OWNER='airflow' AIRFLOW_CTX_DAG_ID='weather_dag' AIRFLOW_CTX_TASK_ID='transform_load_weather_data' AIRFLOW_CTX_EXECUTION_DATE='2025-07-17T07:27:41.504834+00:00' AIRFLOW_CTX_TRY_NUMBER='1' AIRFLOW_CTX_DAG_RUN_ID='manual__2025-07-17T07:27:41.504834+00:00'
[2025-07-17T14:27:48.993+0700] {taskinstance.py:430} INFO - ::endgroup::
[2025-07-17T14:27:49.009+0700] {taskinstance.py:441} INFO - ::group::Post task execution logs
[2025-07-17T14:27:49.010+0700] {taskinstance.py:2905} ERROR - Task failed with exception
Traceback (most recent call last):
  File "/home/menglim/airflow_venv/lib/python3.12/site-packages/airflow/models/taskinstance.py", line 465, in _execute_task
    result = _execute_callable(context=context, **execute_callable_kwargs)
             ^^^^^^^^^^^^^^^^^^^^^^^^^^^^^^^^^^^^^^^^^^^^^^^^^^^^^^^^^^^^^
  File "/home/menglim/airflow_venv/lib/python3.12/site-packages/airflow/models/taskinstance.py", line 432, in _execute_callable
    return execute_callable(context=context, **execute_callable_kwargs)
           ^^^^^^^^^^^^^^^^^^^^^^^^^^^^^^^^^^^^^^^^^^^^^^^^^^^^^^^^^^^^
  File "/home/menglim/airflow_venv/lib/python3.12/site-packages/airflow/models/baseoperator.py", line 400, in wrapper
    return func(self, *args, **kwargs)
           ^^^^^^^^^^^^^^^^^^^^^^^^^^^
  File "/home/menglim/airflow_venv/lib/python3.12/site-packages/airflow/operators/python.py", line 235, in execute
    return_value = self.execute_callable()
                   ^^^^^^^^^^^^^^^^^^^^^^^
  File "/home/menglim/airflow_venv/lib/python3.12/site-packages/airflow/operators/python.py", line 252, in execute_callable
    return self.python_callable(*self.op_args, **self.op_kwargs)
           ^^^^^^^^^^^^^^^^^^^^^^^^^^^^^^^^^^^^^^^^^^^^^^^^^^^^^
  File "/home/menglim/airflow/dags/weather_dag.py", line 51, in transform_load_data
    df_data.to_csv(file_path, index=False)
  File "/home/menglim/airflow_venv/lib/python3.12/site-packages/pandas/util/_decorators.py", line 333, in wrapper
    return func(*args, **kwargs)
           ^^^^^^^^^^^^^^^^^^^^^
  File "/home/menglim/airflow_venv/lib/python3.12/site-packages/pandas/core/generic.py", line 3986, in to_csv
    return DataFrameRenderer(formatter).to_csv(
           ^^^^^^^^^^^^^^^^^^^^^^^^^^^^^^^^^^^^
  File "/home/menglim/airflow_venv/lib/python3.12/site-packages/pandas/io/formats/format.py", line 1014, in to_csv
    csv_formatter.save()
  File "/home/menglim/airflow_venv/lib/python3.12/site-packages/pandas/io/formats/csvs.py", line 251, in save
    with get_handle(
         ^^^^^^^^^^^
  File "/home/menglim/airflow_venv/lib/python3.12/site-packages/pandas/io/common.py", line 749, in get_handle
    check_parent_directory(str(handle))
  File "/home/menglim/airflow_venv/lib/python3.12/site-packages/pandas/io/common.py", line 616, in check_parent_directory
    raise OSError(rf"Cannot save file into a non-existent directory: '{parent}'")
OSError: Cannot save file into a non-existent directory: '/mnt/d/airflow_exports'
[2025-07-17T14:27:49.023+0700] {taskinstance.py:1206} INFO - Marking task as UP_FOR_RETRY. dag_id=weather_dag, task_id=transform_load_weather_data, run_id=manual__2025-07-17T07:27:41.504834+00:00, execution_date=20250717T072741, start_date=20250717T072748, end_date=20250717T072749
[2025-07-17T14:27:49.044+0700] {standard_task_runner.py:110} ERROR - Failed to execute job 17 for task transform_load_weather_data (Cannot save file into a non-existent directory: '/mnt/d/airflow_exports'; 6999)
[2025-07-17T14:27:49.066+0700] {local_task_job_runner.py:240} INFO - Task exited with return code 1
[2025-07-17T14:27:49.074+0700] {taskinstance.py:3498} INFO - 0 downstream tasks scheduled from follow-on schedule check
[2025-07-17T14:27:49.074+0700] {local_task_job_runner.py:222} INFO - ::endgroup::
